Workbook

Sheet Namluvit
A1: OIS | B1: Název zst. | C1: Pozn.
A2: A1 | B2: Vážení cestující, tento autobus vyčká v zastávce …
A3: A2 | B3: … na pravidelný čas odjezdu dle jízdního řádu.
A4: A3 | B4: Vážení cestující, vyčkáváme na přesný čas odjezdu dle jízdního řádu.
A5: H1, H001 | B5: Příští zastávka …
A6: H2, H002 | B6: Zastávka na znamení.
A7: H103 | B7: Přestup na metro …
A8: H104 | B8: ... A.
A9: H105 | B9: ... B.
A10: H106 | B10: ... C.
A11: H107 | B11: ... A a B.
A12: H108 | B12: ... A a C.
A13: H109 | B13: ... B a C.
... A78: H182 | B78: Uvolněte prosím prostor předních dveří.
A79: H183 | B79: Nástup předními dveřmi. Předložte prosím jízdní doklad. | C79: Zní jako stará nahrávka.
A80: H184 | B80: Přestup na linky "S" a další vlakové spoje.
A81: H185 | B81: … na linky "S" a další vlakové spoje.
A82: H186 | B82: Vážení cestující, provoz metra je částečně přerušen. Použijte prosím autobusy náhradní dopravy "XB", které Vás dopraví k nejbližší stanici metra. Děkujeme za pochopení.
A83: H188 | B83: Vážení cestující, z důvodu technické závady tento autobus dále nepokračuje. Přestupte prosím do přistaveného náhradního autobusu.
A84: H191 | B84: Autous není určen pro přepravu cestujících.
A85: H193 | B85: Příští zastávka je na znamení.
A86: H195 | B86: Pozor, změna orientace.
A87: H196 | B87: Pozor, manipulační přejezd.
A88: H197 | B88: Pozor, manipulační přejezd a změna orientace.
A89: H200 | B89: Prosíme …
A90: H201 | B90: Vozidlo plně obsazeno. Vyčkejte prosím na další spoj.
A91: H202 | B91: Vozidlo má poruchu …
... A126: H241 | B126: Uvolněte prostor pro invalidní vozík.
A127: H243 | B127: Tento autobus zde končí, nenastupujte prosím. | C127: Malinko v nahrávce praská.
A128: H260 | B128: Vážení cestující, uvolněte prosím prostor pro invalidní vozík. Děkujeme.
A129: H274 | B129: Přestup na přívoz.
A130: H279 | B130: Vážení cestující, z důvodvodu silné automobilové dopravy pojede tato linka odklonem.
A131: H280 | B131: Vážení cestující, omlouváme se za zpoždění linky, které je zapříčiněno silnou individuální dopravou a špatnou průjezdností trasy.
A132: H281 | B132: Vážení cestující, vyčkáváme na přesný čas odjezdu dle jízdního řádu.
A133: H282 | B133: Zastávka pouze pro nástup.
A134: H283 | B134: Zastávka pouze pro výstup.
A135: H284 | B135: Vyčkáváme na vzájemný přestup.
A136: H285 | B136: Vážení cestující, vyčkáváme na vzájemný přestup v rámci čekací doby. | C136: Syntéza.
A137: H300 | B137: Přestup na vlak.
A138: H301 | B138: Možnost přestupu na železnici.
...

Sheet slozit
A1: displayName | B1: duration | C1: type | D1: icon | E1: text | F1: changeFrom | G1: changeTo | H1: mp3 | I1: mp3 | J1: mp3 | K1: mp3 | L1: mp3
A2: =iconList!B2 -> c_Accessible | B2: 5 | D2: =iconList!A2&iconList!B2&iconList!C2 -> &lt;icon type=&quot;c_Accessible&quot;&gt;&lt;/icon&gt; | E2: =iconList!B2 -> c_Accessible | H2: H239 | N2: =CONCATENATE("<",A$1,">",A2,"</",A$1,">") -> <displayName>c_Accessible</displayName> | O2: =CONCATENATE("<",B$1,">",B2,"</",B$1,">") -> <duration>5</duration> | P2: =CONCATENATE("<",C$1,">",C2,"</",C$1,">") -> <type></type> | Q2: =CONCATENATE("<",D$1,">",D2,"</",D$1,">") -> <icon>&lt;icon type=&quot;c_Accessible&quot;&gt;&lt;/icon&gt;</icon> | R2: =CONCATENATE("<",E$1,">",E2,"</",E$1,">") -> <text>c_Accessible</text> | S2: =CONCATENATE("<",F$1,">",F2,"</",F$1,">") -> <changeFrom></changeFrom> | T2: =CONCATENATE("<",G$1,">",G2,"</",G$1,">") -> <changeTo></changeTo> | U2: =IF(H2<>"",CONCATENATE("<",H$1,">",H2,".mp3","</",H$1,">"),"") -> <mp3>H239.mp3</mp3> | V2: =IF(I2<>"",CONCATENATE("<",I$1,">",I2,".mp3","</",I$1,">"),"") | W2: =IF(J2<>"",CONCATENATE("<",J$1,">",J2,".mp3","</",J$1,">"),"") | X2: =IF(K2<>"",CONCATENATE("<",K$1,">",K2,".mp3","</",K$1,">"),"") | Y2: =CONCATENATE("<announcement>",N2,O2,P2,Q2,R2,S2,T2,U2,V2,W2,X2,"</announcement>") -> <announcement><displayName>c_Accessible</displayName><duration>5</duration><type></type><icon>&lt;icon type=&quot;c_Accessible&quot;&gt;&lt;/icon&gt;</icon><text>c_Accessible</text><changeFrom></changeFrom><changeTo></changeTo><mp3>H239.mp3</mp3></announcement>
A3: =iconList!B3 -> c_Air | B3: 5 | D3: =iconList!A3&iconList!B3&iconList!C3 -> &lt;icon type=&quot;c_Air&quot;&gt;&lt;/icon&gt; | E3: =iconList!B3 -> c_Air | H3: H340 | N3: =CONCATENATE("<",A$1,">",A3,"</",A$1,">") -> <displayName>c_Air</displayName> | O3: =CONCATENATE("<",B$1,">",B3,"</",B$1,">") -> <duration>5</duration> | P3: =CONCATENATE("<",C$1,">",C3,"</",C$1,">") -> <type></type> | Q3: =CONCATENATE("<",D$1,">",D3,"</",D$1,">") -> <icon>&lt;icon type=&quot;c_Air&quot;&gt;&lt;/icon&gt;</icon> | R3: =CONCATENATE("<",E$1,">",E3,"</",E$1,">") -> <text>c_Air</text> | S3: =CONCATENATE("<",F$1,">",F3,"</",F$1,">") -> <changeFrom></changeFrom> | T3: =CONCATENATE("<",G$1,">",G3,"</",G$1,">") -> <changeTo></changeTo> | U3: =IF(H3<>"",CONCATENATE("<",H$1,">",H3,".mp3","</",H$1,">"),"") -> <mp3>H340.mp3</mp3> | V3: =IF(I3<>"",CONCATENATE("<",I$1,">",I3,".mp3","</",I$1,">"),"") | W3: =IF(J3<>"",CONCATENATE("<",J$1,">",J3,".mp3","</",J$1,">"),"") | X3: =IF(K3<>"",CONCATENATE("<",K$1,">",K3,".mp3","</",K$1,">"),"") | Y3: =CONCATENATE("<announcement>",N3,O3,P3,Q3,R3,S3,T3,U3,V3,W3,X3,"</announcement>") -> <announcement><displayName>c_Air</displayName><duration>5</duration><type></type><icon>&lt;icon type=&quot;c_Air&quot;&gt;&lt;/icon&gt;</icon><text>c_Air</text><changeFrom></changeFrom><changeTo></changeTo><mp3>H340.mp3</mp3></announcement>
A4: =iconList!B4 -> c_Bus | B4: 5 | D4: =iconList!A4&iconList!B4&iconList!C4 -> &lt;icon type=&quot;c_Bus&quot;&gt;&lt;/icon&gt; | E4: =iconList!B4 -> c_Bus | H4: H240 | N4: =CONCATENATE("<",A$1,">",A4,"</",A$1,">") -> <displayName>c_Bus</displayName> | O4: =CONCATENATE("<",B$1,">",B4,"</",B$1,">") -> <duration>5</duration> | P4: =CONCATENATE("<",C$1,">",C4,"</",C$1,">") -> <type></type> | Q4: =CONCATENATE("<",D$1,">",D4,"</",D$1,">") -> <icon>&lt;icon type=&quot;c_Bus&quot;&gt;&lt;/icon&gt;</icon> | R4: =CONCATENATE("<",E$1,">",E4,"</",E$1,">") -> <text>c_Bus</text> | S4: =CONCATENATE("<",F$1,">",F4,"</",F$1,">") -> <changeFrom></changeFrom> | T4: =CONCATENATE("<",G$1,">",G4,"</",G$1,">") -> <changeTo></changeTo> | U4: =IF(H4<>"",CONCATENATE("<",H$1,">",H4,".mp3","</",H$1,">"),"") -> <mp3>H240.mp3</mp3> | V4: =IF(I4<>"",CONCATENATE("<",I$1,">",I4,".mp3","</",I$1,">"),"") | W4: =IF(J4<>"",CONCATENATE("<",J$1,">",J4,".mp3","</",J$1,">"),"") | X4: =IF(K4<>"",CONCATENATE("<",K$1,">",K4,".mp3","</",K$1,">"),"") | Y4: =CONCATENATE("<announcement>",N4,O4,P4,Q4,R4,S4,T4,U4,V4,W4,X4,"</announcement>") -> <announcement><displayName>c_Bus</displayName><duration>5</duration><type></type><icon>&lt;icon type=&quot;c_Bus&quot;&gt;&lt;/icon&gt;</icon><text>c_Bus</text><changeFrom></changeFrom><changeTo></changeTo><mp3>H240.mp3</mp3></announcement>
A5: =iconList!B5 -> c_Congestion | B5: 5 | D5: =iconList!A5&iconList!B5&iconList!C5 -> &lt;icon type=&quot;c_Congestion&quot;&gt;&lt;/icon&gt; | E5: =iconList!B5 -> c_Congestion | H5: H260 | N5: =CONCATENATE("<",A$1,">",A5,"</",A$1,">") -> <displayName>c_Congestion</displayName> | O5: =CONCATENATE("<",B$1,">",B5,"</",B$1,">") -> <duration>5</duration> | P5: =CONCATENATE("<",C$1,">",C5,"</",C$1,">") -> <type></type> | Q5: =CONCATENATE("<",D$1,">",D5,"</",D$1,">") -> <icon>&lt;icon type=&quot;c_Congestion&quot;&gt;&lt;/icon&gt;</icon> | R5: =CONCATENATE("<",E$1,">",E5,"</",E$1,">") -> <text>c_Congestion</text> | S5: =CONCATENATE("<",F$1,">",F5,"</",F$1,">") -> <changeFrom></changeFrom> | T5: =CONCATENATE("<",G$1,">",G5,"</",G$1,">") -> <changeTo></changeTo> | U5: =IF(H5<>"",CONCATENATE("<",H$1,">",H5,".mp3","</",H$1,">"),"") -> <mp3>H260.mp3</mp3> | V5: =IF(I5<>"",CONCATENATE("<",I$1,">",I5,".mp3","</",I$1,">"),"") | W5: =IF(J5<>"",CONCATENATE("<",J$1,">",J5,".mp3","</",J$1,">"),"") | X5: =IF(K5<>"",CONCATENATE("<",K$1,">",K5,".mp3","</",K$1,">"),"") | Y5: =CONCATENATE("<announcement>",N5,O5,P5,Q5,R5,S5,T5,U5,V5,W5,X5,"</announcement>") -> <announcement><displayName>c_Congestion</displayName><duration>5</duration><type></type><icon>&lt;icon type=&quot;c_Congestion&quot;&gt;&lt;/icon&gt;</icon><text>c_Congestion</text><changeFrom></changeFrom><changeTo></changeTo><mp3>H260.mp3</mp3></announcement>
A6: =iconList!B6 -> c_Diversion | B6: 5 | D6: =iconList!A6&iconList!B6&iconList!C6 -> &lt;icon type=&quot;c_Diversion&quot;&gt;&lt;/icon&gt; | E6: =iconList!B6 -> c_Diversion | H6: H179 | N6: =CONCATENATE("<",A$1,">",A6,"</",A$1,">") -> <displayName>c_Diversion</displayName> | O6: =CONCATENATE("<",B$1,">",B6,"</",B$1,">") -> <duration>5</duration> | P6: =CONCATENATE("<",C$1,">",C6,"</",C$1,">") -> <type></type> | Q6: =CONCATENATE("<",D$1,">",D6,"</",D$1,">") -> <icon>&lt;icon type=&quot;c_Diversion&quot;&gt;&lt;/icon&gt;</icon> | R6: =CONCATENATE("<",E$1,">",E6,"</",E$1,">") -> <text>c_Diversion</text> | S6: =CONCATENATE("<",F$1,">",F6,"</",F$1,">") -> <changeFrom></changeFrom> | T6: =CONCATENATE("<",G$1,">",G6,"</",G$1,">") -> <changeTo></changeTo> | U6: =IF(H6<>"",CONCATENATE("<",H$1,">",H6,".mp3","</",H$1,">"),"") -> <mp3>H179.mp3</mp3> | V6: =IF(I6<>"",CONCATENATE("<",I$1,">",I6,".mp3","</",I$1,">"),"") | W6: =IF(J6<>"",CONCATENATE("<",J$1,">",J6,".mp3","</",J$1,">"),"") | X6: =IF(K6<>"",CONCATENATE("<",K$1,">",K6,".mp3","</",K$1,">"),"") | Y6: =CONCATENATE("<announcement>",N6,O6,P6,Q6,R6,S6,T6,U6,V6,W6,X6,"</announcement>") -> <announcement><displayName>c_Diversion</displayName><duration>5</duration><type></type><icon>&lt;icon type=&quot;c_Diversion&quot;&gt;&lt;/icon&gt;</icon><text>c_Diversion</text><changeFrom></changeFrom><changeTo></changeTo><mp3>H179.mp3</mp3></announcement>
A7: =iconList!B7 -> c_Exclamation | B7: 5 | D7: =iconList!A7&iconList!B7&iconList!C7 -> &lt;icon type=&quot;c_Exclamation&quot;&gt;&lt;/icon&gt; | E7: =iconList!B7 -> c_Exclamation | H7: H281 | N7: =CONCATENATE("<",A$1,">",A7,"</",A$1,">") -> <displayName>c_Exclamation</displayName> | O7: =CONCATENATE("<",B$1,">",B7,"</",B$1,">") -> <duration>5</duration> | P7: =CONCATENATE("<",C$1,">",C7,"</",C$1,">") -> <type></type> | Q7: =CONCATENATE("<",D$1,">",D7,"</",D$1,">") -> <icon>&lt;icon type=&quot;c_Exclamation&quot;&gt;&lt;/icon&gt;</icon> | R7: =CONCATENATE("<",E$1,">",E7,"</",E$1,">") -> <text>c_Exclamation</text> | S7: =CONCATENATE("<",F$1,">",F7,"</",F$1,">") -> <changeFrom></changeFrom> | T7: =CONCATENATE("<",G$1,">",G7,"</",G$1,">") -> <changeTo></changeTo> | U7: =IF(H7<>"",CONCATENATE("<",H$1,">",H7,".mp3","</",H$1,">"),"") -> <mp3>H281.mp3</mp3> | V7: =IF(I7<>"",CONCATENATE("<",I$1,">",I7,".mp3","</",I$1,">"),"") | W7: =IF(J7<>"",CONCATENATE("<",J$1,">",J7,".mp3","</",J$1,">"),"") | X7: =IF(K7<>"",CONCATENATE("<",K$1,">",K7,".mp3","</",K$1,">"),"") | Y7: =CONCATENATE("<announcement>",N7,O7,P7,Q7,R7,S7,T7,U7,V7,W7,X7,"</announcement>") -> <announcement><displayName>c_Exclamation</displayName><duration>5</duration><type></type><icon>&lt;icon type=&quot;c_Exclamation&quot;&gt;&lt;/icon&gt;</icon><text>c_Exclamation</text><changeFrom></changeFrom><changeTo></changeTo><mp3>H281.mp3</mp3></announcement>
A8: =iconList!B8 -> c_Ferry | B8: 5 | D8: =iconList!A8&iconList!B8&iconList!C8 -> &lt;icon type=&quot;c_Ferry&quot;&gt;&lt;/icon&gt; | E8: =iconList!B8 -> c_Ferry | H8: H284 | N8: =CONCATENATE("<",A$1,">",A8,"</",A$1,">") -> <displayName>c_Ferry</displayName> | O8: =CONCATENATE("<",B$1,">",B8,"</",B$1,">") -> <duration>5</duration> | P8: =CONCATENATE("<",C$1,">",C8,"</",C$1,">") -> <type></type> | Q8: =CONCATENATE("<",D$1,">",D8,"</",D$1,">") -> <icon>&lt;icon type=&quot;c_Ferry&quot;&gt;&lt;/icon&gt;</icon> | R8: =CONCATENATE("<",E$1,">",E8,"</",E$1,">") -> <text>c_Ferry</text> | S8: =CONCATENATE("<",F$1,">",F8,"</",F$1,">") -> <changeFrom></changeFrom> | T8: =CONCATENATE("<",G$1,">",G8,"</",G$1,">") -> <changeTo></changeTo> | U8: =IF(H8<>"",CONCATENATE("<",H$1,">",H8,".mp3","</",H$1,">"),"") -> <mp3>H284.mp3</mp3> | V8: =IF(I8<>"",CONCATENATE("<",I$1,">",I8,".mp3","</",I$1,">"),"") | W8: =IF(J8<>"",CONCATENATE("<",J$1,">",J8,".mp3","</",J$1,">"),"") | X8: =IF(K8<>"",CONCATENATE("<",K$1,">",K8,".mp3","</",K$1,">"),"") | Y8: =CONCATENATE("<announcement>",N8,O8,P8,Q8,R8,S8,T8,U8,V8,W8,X8,"</announcement>") -> <announcement><displayName>c_Ferry</displayName><duration>5</duration><type></type><icon>&lt;icon type=&quot;c_Ferry&quot;&gt;&lt;/icon&gt;</icon><text>c_Ferry</text><changeFrom></changeFrom><changeTo></changeTo><mp3>H284.mp3</mp3></announcement>
A9: =iconList!B9 -> c_Funicular | B9: 5 | D9: =iconList!A9&iconList!B9&iconList!C9 -> &lt;icon type=&quot;c_Funicular&quot;&gt;&lt;/icon&gt; | E9: =iconList!B9 -> c_Funicular | N9: =CONCATENATE("<",A$1,">",A9,"</",A$1,">") -> <displayName>c_Funicular</displayName> | O9: =CONCATENATE("<",B$1,">",B9,"</",B$1,">") -> <duration>5</duration> | P9: =CONCATENATE("<",C$1,">",C9,"</",C$1,">") -> <type></type> | Q9: =CONCATENATE("<",D$1,">",D9,"</",D$1,">") -> <icon>&lt;icon type=&quot;c_Funicular&quot;&gt;&lt;/icon&gt;</icon> | R9: =CONCATENATE("<",E$1,">",E9,"</",E$1,">") -> <text>c_Funicular</text> | S9: =CONCATENATE("<",F$1,">",F9,"</",F$1,">") -> <changeFrom></changeFrom> | T9: =CONCATENATE("<",G$1,">",G9,"</",G$1,">") -> <changeTo></changeTo> | U9: =IF(H9<>"",CONCATENATE("<",H$1,">",H9,".mp3","</",H$1,">"),"") | V9: =IF(I9<>"",CONCATENATE("<",I$1,">",I9,".mp3","</",I$1,">"),"") | W9: =IF(J9<>"",CONCATENATE("<",J$1,">",J9,".mp3","</",J$1,">"),"") | X9: =IF(K9<>"",CONCATENATE("<",K$1,">",K9,".mp3","</",K$1,">"),"") | Y9: =CONCATENATE("<announcement>",N9,O9,P9,Q9,R9,S9,T9,U9,V9,W9,X9,"</announcement>") -> <announcement><displayName>c_Funicular</displayName><duration>5</duration><type></type><icon>&lt;icon type=&quot;c_Funicular&quot;&gt;&lt;/icon&gt;</icon><text>c_Funicular</text><changeFrom></changeFrom><changeTo></changeTo></announcement>
A10: =iconList!B10 -> c_GoFurther | B10: 5 | D10: =iconList!A10&iconList!B10&iconList!C10 -> &lt;icon type=&quot;c_GoFurther&quot;&gt;&lt;/icon&gt; | E10: =iconList!B10 -> c_GoFurther | H10: H279 | N10: =CONCATENATE("<",A$1,">",A10,"</",A$1,">") -> <displayName>c_GoFurther</displayName> | O10: =CONCATENATE("<",B$1,">",B10,"</",B$1,">") -> <duration>5</duration> | P10: =CONCATENATE("<",C$1,">",C10,"</",C$1,">") -> <type></type> | Q10: =CONCATENATE("<",D$1,">",D10,"</",D$1,">") -> <icon>&lt;icon type=&quot;c_GoFurther&quot;&gt;&lt;/icon&gt;</icon> | R10: =CONCATENATE("<",E$1,">",E10,"</",E$1,">") -> <text>c_GoFurther</text> | S10: =CONCATENATE("<",F$1,">",F10,"</",F$1,">") -> <changeFrom></changeFrom> | T10: =CONCATENATE("<",G$1,">",G10,"</",G$1,">") -> <changeTo></changeTo> | U10: =IF(H10<>"",CONCATENATE("<",H$1,">",H10,".mp3","</",H$1,">"),"") -> <mp3>H279.mp3</mp3> | V10: =IF(I10<>"",CONCATENATE("<",I$1,">",I10,".mp3","</",I$1,">"),"") | W10: =IF(J10<>"",CONCATENATE("<",J$1,">",J10,".mp3","</",J$1,">"),"") | X10: =IF(K10<>"",CONCATENATE("<",K$1,">",K10,".mp3","</",K$1,">"),"") | Y10: =CONCATENATE("<announcement>",N10,O10,P10,Q10,R10,S10,T10,U10,V10,W10,X10,"</announcement>") -> <announcement><displayName>c_GoFurther</displayName><duration>5</duration><type></type><icon>&lt;icon type=&quot;c_GoFurther&quot;&gt;&lt;/icon&gt;</icon><text>c_GoFurther</text><changeFrom></changeFrom><changeTo></changeTo><mp3>H279.mp3</mp3></announcement>
A11: =iconList!B11 -> c_Children | B11: 5 | D11: =iconList!A11&iconList!B11&iconList!C11 -> &lt;icon type=&quot;c_Children&quot;&gt;&lt;/icon&gt; | E11: =iconList!B11 -> c_Children | N11: =CONCATENATE("<",A$1,">",A11,"</",A$1,">") -> <displayName>c_Children</displayName> | O11: =CONCATENATE("<",B$1,">",B11,"</",B$1,">") -> <duration>5</duration> | P11: =CONCATENATE("<",C$1,">",C11,"</",C$1,">") -> <type></type> | Q11: =CONCATENATE("<",D$1,">",D11,"</",D$1,">") -> <icon>&lt;icon type=&quot;c_Children&quot;&gt;&lt;/icon&gt;</icon> | R11: =CONCATENATE("<",E$1,">",E11,"</",E$1,">") -> <text>c_Children</text> | S11: =CONCATENATE("<",F$1,">",F11,"</",F$1,">") -> <changeFrom></changeFrom> | T11: =CONCATENATE("<",G$1,">",G11,"</",G$1,">") -> <changeTo></changeTo> | U11: =IF(H11<>"",CONCATENATE("<",H$1,">",H11,".mp3","</",H$1,">"),"") | V11: =IF(I11<>"",CONCATENATE("<",I$1,">",I11,".mp3","</",I$1,">"),"") | W11: =IF(J11<>"",CONCATENATE("<",J$1,">",J11,".mp3","</",J$1,">"),"") | X11: =IF(K11<>"",CONCATENATE("<",K$1,">",K11,".mp3","</",K$1,">"),"") | Y11: =CONCATENATE("<announcement>",N11,O11,P11,Q11,R11,S11,T11,U11,V11,W11,X11,"</announcement>") -> <announcement><displayName>c_Children</displayName><duration>5</duration><type></type><icon>&lt;icon type=&quot;c_Children&quot;&gt;&lt;/icon&gt;</icon><text>c_Children</text><changeFrom></changeFrom><changeTo></changeTo></announcement>
A12: =iconList!B12 -> c_Info | B12: 5 | D12: =iconList!A12&iconList!B12&iconList!C12 -> &lt;icon type=&quot;c_Info&quot;&gt;&lt;/icon&gt; | E12: =iconList!B12 -> c_Info | H12: H280 | N12: =CONCATENATE("<",A$1,">",A12,"</",A$1,">") -> <displayName>c_Info</displayName> | O12: =CONCATENATE("<",B$1,">",B12,"</",B$1,">") -> <duration>5</duration> | P12: =CONCATENATE("<",C$1,">",C12,"</",C$1,">") -> <type></type> | Q12: =CONCATENATE("<",D$1,">",D12,"</",D$1,">") -> <icon>&lt;icon type=&quot;c_Info&quot;&gt;&lt;/icon&gt;</icon> | R12: =CONCATENATE("<",E$1,">",E12,"</",E$1,">") -> <text>c_Info</text> | S12: =CONCATENATE("<",F$1,">",F12,"</",F$1,">") -> <changeFrom></changeFrom> | T12: =CONCATENATE("<",G$1,">",G12,"</",G$1,">") -> <changeTo></changeTo> | U12: =IF(H12<>"",CONCATENATE("<",H$1,">",H12,".mp3","</",H$1,">"),"") -> <mp3>H280.mp3</mp3> | V12: =IF(I12<>"",CONCATENATE("<",I$1,">",I12,".mp3","</",I$1,">"),"") | W12: =IF(J12<>"",CONCATENATE("<",J$1,">",J12,".mp3","</",J$1,">"),"") | X12: =IF(K12<>"",CONCATENATE("<",K$1,">",K12,".mp3","</",K$1,">"),"") | Y12: =CONCATENATE("<announcement>",N12,O12,P12,Q12,R12,S12,T12,U12,V12,W12,X12,"</announcement>") -> <announcement><displayName>c_Info</displayName><duration>5</duration><type></type><icon>&lt;icon type=&quot;c_Info&quot;&gt;&lt;/icon&gt;</icon><text>c_Info</text><changeFrom></changeFrom><changeTo></changeTo><mp3>H280.mp3</mp3></announcement>
A13: =iconList!B13 -> c_Luggage | B13: 5 | D13: =iconList!A13&iconList!B13&iconList!C13 -> &lt;icon type=&quot;c_Luggage&quot;&gt;&lt;/icon&gt; | E13: =iconList!B13 -> c_Luggage | F13: 6.8 | G13: 7 | N13: =CONCATENATE("<",A$1,">",A13,"</",A$1,">") -> <displayName>c_Luggage</displayName> | O13: =CONCATENATE("<",B$1,">",B13,"</",B$1,">") -> <duration>5</duration> | P13: =CONCATENATE("<",C$1,">",C13,"</",C$1,">") -> <type></type> | Q13: =CONCATENATE("<",D$1,">",D13,"</",D$1,">") -> <icon>&lt;icon type=&quot;c_Luggage&quot;&gt;&lt;/icon&gt;</icon> | R13: =CONCATENATE("<",E$1,">",E13,"</",E$1,">") -> <text>c_Luggage</text> | S13: =CONCATENATE("<",F$1,">",F13,"</",F$1,">") -> <changeFrom>6,8</changeFrom> | T13: =CONCATENATE("<",G$1,">",G13,"</",G$1,">") -> <changeTo>7</changeTo> | U13: =IF(H13<>"",CONCATENATE("<",H$1,">",H13,".mp3","</",H$1,">"),"") | V13: =IF(I13<>"",CONCATENATE("<",I$1,">",I13,".mp3","</",I$1,">"),"") | W13: =IF(J13<>"",CONCATENATE("<",J$1,">",J13,".mp3","</",J$1,">"),"") | X13: =IF(K13<>"",CONCATENATE("<",K$1,">",K13,".mp3","</",K$1,">"),"") | Y13: =CONCATENATE("<announcement>",N13,O13,P13,Q13,R13,S13,T13,U13,V13,W13,X13,"</announcement>") -> <announcement><displayName>c_Luggage</displayName><duration>5</duration><type></type><icon>&lt;icon type=&quot;c_Luggage&quot;&gt;&lt;/icon&gt;</icon><text>c_Luggage</text><changeFrom>6,8</changeFrom><changeTo>7</changeTo></announcement>
A14: =iconList!B14 -> c_Night | B14: 5 | D14: =iconList!A14&iconList!B14&iconList!C14 -> &lt;icon type=&quot;c_Night&quot;&gt;&lt;/icon&gt; | E14: =iconList!B14 -> c_Night | F14: 123 | G14: XS2 | N14: =CONCATENATE("<",A$1,">",A14,"</",A$1,">") -> <displayName>c_Night</displayName> | O14: =CONCATENATE("<",B$1,">",B14,"</",B$1,">") -> <duration>5</duration> | P14: =CONCATENATE("<",C$1,">",C14,"</",C$1,">") -> <type></type> | Q14: =CONCATENATE("<",D$1,">",D14,"</",D$1,">") -> <icon>&lt;icon type=&quot;c_Night&quot;&gt;&lt;/icon&gt;</icon> | R14: =CONCATENATE("<",E$1,">",E14,"</",E$1,">") -> <text>c_Night</text> | S14: =CONCATENATE("<",F$1,">",F14,"</",F$1,">") -> <changeFrom>123</changeFrom> | T14: =CONCATENATE("<",G$1,">",G14,"</",G$1,">") -> <changeTo>XS2</changeTo> | U14: =IF(H14<>"",CONCATENATE("<",H$1,">",H14,".mp3","</",H$1,">"),"") | V14: =IF(I14<>"",CONCATENATE("<",I$1,">",I14,".mp3","</",I$1,">"),"") | W14: =IF(J14<>"",CONCATENATE("<",J$1,">",J14,".mp3","</",J$1,">"),"") | X14: =IF(K14<>"",CONCATENATE("<",K$1,">",K14,".mp3","</",K$1,">"),"") | Y14: =CONCATENATE("<announcement>",N14,O14,P14,Q14,R14,S14,T14,U14,V14,W14,X14,"</announcement>") -> <announcement><displayName>c_Night</displayName><duration>5</duration><type></type><icon>&lt;icon type=&quot;c_Night&quot;&gt;&lt;/icon&gt;</icon><text>c_Night</text><changeFrom>123</changeFrom><changeTo>XS2</changeTo></announcement>
A15: =iconList!B15 -> c_NightInv | B15: 5 | D15: =iconList!A15&iconList!B15&iconList!C15 -> &lt;icon type=&quot;c_NightInv&quot;&gt;&lt;/icon&gt; | E15: =iconList!B15 -> c_NightInv | N15: =CONCATENATE("<",A$1,">",A15,"</",A$1,">") -> <displayName>c_NightInv</displayName> | O15: =CONCATENATE("<",B$1,">",B15,"</",B$1,">") -> <duration>5</duration> | P15: =CONCATENATE("<",C$1,">",C15,"</",C$1,">") -> <type></type> | Q15: =CONCATENATE("<",D$1,">",D15,"</",D$1,">") -> <icon>&lt;icon type=&quot;c_NightInv&quot;&gt;&lt;/icon&gt;</icon> | R15: =CONCATENATE("<",E$1,">",E15,"</",E$1,">") -> <text>c_NightInv</text> | S15: =CONCATENATE("<",F$1,">",F15,"</",F$1,">") -> <changeFrom></changeFrom> | T15: =CONCATENATE("<",G$1,">",G15,"</",G$1,">") -> <changeTo></changeTo> | U15: =IF(H15<>"",CONCATENATE("<",H$1,">",H15,".mp3","</",H$1,">"),"") | V15: =IF(I15<>"",CONCATENATE("<",I$1,">",I15,".mp3","</",I$1,">"),"") | W15: =IF(J15<>"",CONCATENATE("<",J$1,">",J15,".mp3","</",J$1,">"),"") | X15: =IF(K15<>"",CONCATENATE("<",K$1,">",K15,".mp3","</",K$1,">"),"") | Y15: =CONCATENATE("<announcement>",N15,O15,P15,Q15,R15,S15,T15,U15,V15,W15,X15,"</announcement>") -> <announcement><displayName>c_NightInv</displayName><duration>5</duration><type></type><icon>&lt;icon type=&quot;c_NightInv&quot;&gt;&lt;/icon&gt;</icon><text>c_NightInv</text><changeFrom></changeFrom><changeTo></changeTo></announcement>
A16: =iconList!B16 -> c_NoFood | B16: 5 | D16: =iconList!A16&iconList!B16&iconList!C16 -> &lt;icon type=&quot;c_NoFood&quot;&gt;&lt;/icon&gt; | E16: =iconList!B16 -> c_NoFood | N16: =CONCATENATE("<",A$1,">",A16,"</",A$1,">") -> <displayName>c_NoFood</displayName> | O16: =CONCATENATE("<",B$1,">",B16,"</",B$1,">") -> <duration>5</duration> | P16: =CONCATENATE("<",C$1,">",C16,"</",C$1,">") -> <type></type> | Q16: =CONCATENATE("<",D$1,">",D16,"</",D$1,">") -> <icon>&lt;icon type=&quot;c_NoFood&quot;&gt;&lt;/icon&gt;</icon> | R16: =CONCATENATE("<",E$1,">",E16,"</",E$1,">") -> <text>c_NoFood</text> | S16: =CONCATENATE("<",F$1,">",F16,"</",F$1,">") -> <changeFrom></changeFrom> | T16: =CONCATENATE("<",G$1,">",G16,"</",G$1,">") -> <changeTo></changeTo> | U16: =IF(H16<>"",CONCATENATE("<",H$1,">",H16,".mp3","</",H$1,">"),"") | V16: =IF(I16<>"",CONCATENATE("<",I$1,">",I16,".mp3","</",I$1,">"),"") | W16: =IF(J16<>"",CONCATENATE("<",J$1,">",J16,".mp3","</",J$1,">"),"") | X16: =IF(K16<>"",CONCATENATE("<",K$1,">",K16,".mp3","</",K$1,">"),"") | Y16: =CONCATENATE("<announcement>",N16,O16,P16,Q16,R16,S16,T16,U16,V16,W16,X16,"</announcement>") -> <announcement><displayName>c_NoFood</displayName><duration>5</duration><type></type><icon>&lt;icon type=&quot;c_NoFood&quot;&gt;&lt;/icon&gt;</icon><text>c_NoFood</text><changeFrom></changeFrom><changeTo></changeTo></announcement>
A17: =iconList!B17 -> c_NoFoodInv | B17: 5 | D17: =iconList!A17&iconList!B17&iconList!C17 -> &lt;icon type=&quot;c_NoFoodInv&quot;&gt;&lt;/icon&gt; | E17: =iconList!B17 -> c_NoFoodInv | N17: =CONCATENATE("<",A$1,">",A17,"</",A$1,">") -> <displayName>c_NoFoodInv</displayName> | O17: =CONCATENATE("<",B$1,">",B17,"</",B$1,">") -> <duration>5</duration> | P17: =CONCATENATE("<",C$1,">",C17,"</",C$1,">") -> <type></type> | Q17: =CONCATENATE("<",D$1,">",D17,"</",D$1,">") -> <icon>&lt;icon type=&quot;c_NoFoodInv&quot;&gt;&lt;/icon&gt;</icon> | R17: =CONCATENATE("<",E$1,">",E17,"</",E$1,">") -> <text>c_NoFoodInv</text> | S17: =CONCATENATE("<",F$1,">",F17,"</",F$1,">") -> <changeFrom></changeFrom> | T17: =CONCATENATE("<",G$1,">",G17,"</",G$1,">") -> <changeTo></changeTo> | U17: =IF(H17<>"",CONCATENATE("<",H$1,">",H17,".mp3","</",H$1,">"),"") | V17: =IF(I17<>"",CONCATENATE("<",I$1,">",I17,".mp3","</",I$1,">"),"") | W17: =IF(J17<>"",CONCATENATE("<",J$1,">",J17,".mp3","</",J$1,">"),"") | X17: =IF(K17<>"",CONCATENATE("<",K$1,">",K17,".mp3","</",K$1,">"),"") | Y17: =CONCATENATE("<announcement>",N17,O17,P17,Q17,R17,S17,T17,U17,V17,W17,X17,"</announcement>") -> <announcement><displayName>c_NoFoodInv</displayName><duration>5</duration><type></type><icon>&lt;icon type=&quot;c_NoFoodInv&quot;&gt;&lt;/icon&gt;</icon><text>c_NoFoodInv</text><changeFrom></changeFrom><changeTo></changeTo></announcement>
A18: =iconList!B18 -> c_Pid | B18: 5 | D18: =iconList!A18&iconList!B18&iconList!C18 -> &lt;icon type=&quot;c_Pid&quot;&gt;&lt;/icon&gt; | E18: =iconList!B18 -> c_Pid | N18: =CONCATENATE("<",A$1,">",A18,"</",A$1,">") -> <displayName>c_Pid</displayName> | O18: =CONCATENATE("<",B$1,">",B18,"</",B$1,">") -> <duration>5</duration> | P18: =CONCATENATE("<",C$1,">",C18,"</",C$1,">") -> <type></type> | Q18: =CONCATENATE("<",D$1,">",D18,"</",D$1,">") -> <icon>&lt;icon type=&quot;c_Pid&quot;&gt;&lt;/icon&gt;</icon> | R18: =CONCATENATE("<",E$1,">",E18,"</",E$1,">") -> <text>c_Pid</text> | S18: =CONCATENATE("<",F$1,">",F18,"</",F$1,">") -> <changeFrom></changeFrom> | T18: =CONCATENATE("<",G$1,">",G18,"</",G$1,">") -> <changeTo></changeTo> | U18: =IF(H18<>"",CONCATENATE("<",H$1,">",H18,".mp3","</",H$1,">"),"") | V18: =IF(I18<>"",CONCATENATE("<",I$1,">",I18,".mp3","</",I$1,">"),"") | W18: =IF(J18<>"",CONCATENATE("<",J$1,">",J18,".mp3","</",J$1,">"),"") | X18: =IF(K18<>"",CONCATENATE("<",K$1,">",K18,".mp3","</",K$1,">"),"") | Y18: =CONCATENATE("<announcement>",N18,O18,P18,Q18,R18,S18,T18,U18,V18,W18,X18,"</announcement>") -> <announcement><displayName>c_Pid</displayName><duration>5</duration><type></type><icon>&lt;icon type=&quot;c_Pid&quot;&gt;&lt;/icon&gt;</icon><text>c_Pid</text><changeFrom></changeFrom><changeTo></changeTo></announcement>
A19: =iconList!B19 -> c_Pram | B19: 5 | D19: =iconList!A19&iconList!B19&iconList!C19 -> &lt;icon type=&quot;c_Pram&quot;&gt;&lt;/icon&gt; | E19: =iconList!B19 -> c_Pram | N19: =CONCATENATE("<",A$1,">",A19,"</",A$1,">") -> <displayName>c_Pram</displayName> | O19: =CONCATENATE("<",B$1,">",B19,"</",B$1,">") -> <duration>5</duration> | P19: =CONCATENATE("<",C$1,">",C19,"</",C$1,">") -> <type></type> | Q19: =CONCATENATE("<",D$1,">",D19,"</",D$1,">") -> <icon>&lt;icon type=&quot;c_Pram&quot;&gt;&lt;/icon&gt;</icon> | R19: =CONCATENATE("<",E$1,">",E19,"</",E$1,">") -> <text>c_Pram</text> | S19: =CONCATENATE("<",F$1,">",F19,"</",F$1,">") -> <changeFrom></changeFrom> | T19: =CONCATENATE("<",G$1,">",G19,"</",G$1,">") -> <changeTo></changeTo> | U19: =IF(H19<>"",CONCATENATE("<",H$1,">",H19,".mp3","</",H$1,">"),"") | V19: =IF(I19<>"",CONCATENATE("<",I$1,">",I19,".mp3","</",I$1,">"),"") | W19: =IF(J19<>"",CONCATENATE("<",J$1,">",J19,".mp3","</",J$1,">"),"") | X19: =IF(K19<>"",CONCATENATE("<",K$1,">",K19,".mp3","</",K$1,">"),"") | Y19: =CONCATENATE("<announcement>",N19,O19,P19,Q19,R19,S19,T19,U19,V19,W19,X19,"</announcement>") -> <announcement><displayName>c_Pram</displayName><duration>5</duration><type></type><icon>&lt;icon type=&quot;c_Pram&quot;&gt;&lt;/icon&gt;</icon><text>c_Pram</text><changeFrom></changeFrom><changeTo></changeTo></announcement>
A20: =iconList!B20 -> c_ReplacementService | B20: 5 | D20: =iconList!A20&iconList!B20&iconList!C20 -> &lt;icon type=&quot;c_ReplacementService&quot;&gt;&lt;/icon&gt; | E20: =iconList!B20 -> c_ReplacementService | H20: H350 | N20: =CONCATENATE("<",A$1,">",A20,"</",A$1,">") -> <displayName>c_ReplacementService</displayName> | O20: =CONCATENATE("<",B$1,">",B20,"</",B$1,">") -> <duration>5</duration> | P20: =CONCATENATE("<",C$1,">",C20,"</",C$1,">") -> <type></type> | Q20: =CONCATENATE("<",D$1,">",D20,"</",D$1,">") -> <icon>&lt;icon type=&quot;c_ReplacementService&quot;&gt;&lt;/icon&gt;</icon> | R20: =CONCATENATE("<",E$1,">",E20,"</",E$1,">") -> <text>c_ReplacementService</text> | S20: =CONCATENATE("<",F$1,">",F20,"</",F$1,">") -> <changeFrom></changeFrom> | T20: =CONCATENATE("<",G$1,">",G20,"</",G$1,">") -> <changeTo></changeTo> | U20: =IF(H20<>"",CONCATENATE("<",H$1,">",H20,".mp3","</",H$1,">"),"") -> <mp3>H350.mp3</mp3> | V20: =IF(I20<>"",CONCATENATE("<",I$1,">",I20,".mp3","</",I$1,">"),"") | W20: =IF(J20<>"",CONCATENATE("<",J$1,">",J20,".mp3","</",J$1,">"),"") | X20: =IF(K20<>"",CONCATENATE("<",K$1,">",K20,".mp3","</",K$1,">"),"") | Y20: =CONCATENATE("<announcement>",N20,O20,P20,Q20,R20,S20,T20,U20,V20,W20,X20,"</announcement>") -> <announcement><displayName>c_ReplacementService</displayName><duration>5</duration><type></type><icon>&lt;icon type=&quot;c_ReplacementService&quot;&gt;&lt;/icon&gt;</icon><text>c_ReplacementService</text><changeFrom></changeFrom><changeTo></changeTo><mp3>H350.mp3</mp3></announcement>
A21: =iconList!B21 -> c_RequestStop | B21: 5 | D21: =iconList!A21&iconList!B21&iconList!C21 -> &lt;icon type=&quot;c_RequestStop&quot;&gt;&lt;/icon&gt; | E21: =iconList!B21 -> c_RequestStop | H21: H205 | N21: =CONCATENATE("<",A$1,">",A21,"</",A$1,">") -> <displayName>c_RequestStop</displayName> | O21: =CONCATENATE("<",B$1,">",B21,"</",B$1,">") -> <duration>5</duration> | P21: =CONCATENATE("<",C$1,">",C21,"</",C$1,">") -> <type></type> | Q21: =CONCATENATE("<",D$1,">",D21,"</",D$1,">") -> <icon>&lt;icon type=&quot;c_RequestStop&quot;&gt;&lt;/icon&gt;</icon> | R21: =CONCATENATE("<",E$1,">",E21,"</",E$1,">") -> <text>c_RequestStop</text> | S21: =CONCATENATE("<",F$1,">",F21,"</",F$1,">") -> <changeFrom></changeFrom> | T21: =CONCATENATE("<",G$1,">",G21,"</",G$1,">") -> <changeTo></changeTo> | U21: =IF(H21<>"",CONCATENATE("<",H$1,">",H21,".mp3","</",H$1,">"),"") -> <mp3>H205.mp3</mp3> | V21: =IF(I21<>"",CONCATENATE("<",I$1,">",I21,".mp3","</",I$1,">"),"") | W21: =IF(J21<>"",CONCATENATE("<",J$1,">",J21,".mp3","</",J$1,">"),"") | X21: =IF(K21<>"",CONCATENATE("<",K$1,">",K21,".mp3","</",K$1,">"),"") | Y21: =CONCATENATE("<announcement>",N21,O21,P21,Q21,R21,S21,T21,U21,V21,W21,X21,"</announcement>") -> <announcement><displayName>c_RequestStop</displayName><duration>5</duration><type></type><icon>&lt;icon type=&quot;c_RequestStop&quot;&gt;&lt;/icon&gt;</icon><text>c_RequestStop</text><changeFrom></changeFrom><changeTo></changeTo><mp3>H205.mp3</mp3></announcement>
A22: =iconList!B22 -> c_RequestStopInv | B22: 5 | D22: =iconList!A22&iconList!B22&iconList!C22 -> &lt;icon type=&quot;c_RequestStopInv&quot;&gt;&lt;/icon&gt; | E22: =iconList!B22 -> c_RequestStopInv | H22: H162 | N22: =CONCATENATE("<",A$1,">",A22,"</",A$1,">") -> <displayName>c_RequestStopInv</displayName> | O22: =CONCATENATE("<",B$1,">",B22,"</",B$1,">") -> <duration>5</duration> | P22: =CONCATENATE("<",C$1,">",C22,"</",C$1,">") -> <type></type> | Q22: =CONCATENATE("<",D$1,">",D22,"</",D$1,">") -> <icon>&lt;icon type=&quot;c_RequestStopInv&quot;&gt;&lt;/icon&gt;</icon> | R22: =CONCATENATE("<",E$1,">",E22,"</",E$1,">") -> <text>c_RequestStopInv</text> | S22: =CONCATENATE("<",F$1,">",F22,"</",F$1,">") -> <changeFrom></changeFrom> | T22: =CONCATENATE("<",G$1,">",G22,"</",G$1,">") -> <changeTo></changeTo> | U22: =IF(H22<>"",CONCATENATE("<",H$1,">",H22,".mp3","</",H$1,">"),"") -> <mp3>H162.mp3</mp3> | V22: =IF(I22<>"",CONCATENATE("<",I$1,">",I22,".mp3","</",I$1,">"),"") | W22: =IF(J22<>"",CONCATENATE("<",J$1,">",J22,".mp3","</",J$1,">"),"") | X22: =IF(K22<>"",CONCATENATE("<",K$1,">",K22,".mp3","</",K$1,">"),"") | Y22: =CONCATENATE("<announcement>",N22,O22,P22,Q22,R22,S22,T22,U22,V22,W22,X22,"</announcement>") -> <announcement><displayName>c_RequestStopInv</displayName><duration>5</duration><type></type><icon>&lt;icon type=&quot;c_RequestStopInv&quot;&gt;&lt;/icon&gt;</icon><text>c_RequestStopInv</text><changeFrom></changeFrom><changeTo></changeTo><mp3>H162.mp3</mp3></announcement>
A23: =iconList!B23 -> c_SBahn | B23: 5 | D23: =iconList!A23&iconList!B23&iconList!C23 -> &lt;icon type=&quot;c_SBahn&quot;&gt;&lt;/icon&gt; | E23: =iconList!B23 -> c_SBahn | H23: H164 | N23: =CONCATENATE("<",A$1,">",A23,"</",A$1,">") -> <displayName>c_SBahn</displayName> | O23: =CONCATENATE("<",B$1,">",B23,"</",B$1,">") -> <duration>5</duration> | P23: =CONCATENATE("<",C$1,">",C23,"</",C$1,">") -> <type></type> | Q23: =CONCATENATE("<",D$1,">",D23,"</",D$1,">") -> <icon>&lt;icon type=&quot;c_SBahn&quot;&gt;&lt;/icon&gt;</icon> | R23: =CONCATENATE("<",E$1,">",E23,"</",E$1,">") -> <text>c_SBahn</text> | S23: =CONCATENATE("<",F$1,">",F23,"</",F$1,">") -> <changeFrom></changeFrom> | T23: =CONCATENATE("<",G$1,">",G23,"</",G$1,">") -> <changeTo></changeTo> | U23: =IF(H23<>"",CONCATENATE("<",H$1,">",H23,".mp3","</",H$1,">"),"") -> <mp3>H164.mp3</mp3> | V23: =IF(I23<>"",CONCATENATE("<",I$1,">",I23,".mp3","</",I$1,">"),"") | W23: =IF(J23<>"",CONCATENATE("<",J$1,">",J23,".mp3","</",J$1,">"),"") | X23: =IF(K23<>"",CONCATENATE("<",K$1,">",K23,".mp3","</",K$1,">"),"") | Y23: =CONCATENATE("<announcement>",N23,O23,P23,Q23,R23,S23,T23,U23,V23,W23,X23,"</announcement>") -> <announcement><displayName>c_SBahn</displayName><duration>5</duration><type></type><icon>&lt;icon type=&quot;c_SBahn&quot;&gt;&lt;/icon&gt;</icon><text>c_SBahn</text><changeFrom></changeFrom><changeTo></changeTo><mp3>H164.mp3</mp3></announcement>
A24: =iconList!B24 -> c_Train | B24: 5 | D24: =iconList!A24&iconList!B24&iconList!C24 -> &lt;icon type=&quot;c_Train&quot;&gt;&lt;/icon&gt; | E24: =iconList!B24 -> c_Train | H24: H183 | N24: =CONCATENATE("<",A$1,">",A24,"</",A$1,">") -> <displayName>c_Train</displayName> | O24: =CONCATENATE("<",B$1,">",B24,"</",B$1,">") -> <duration>5</duration> | P24: =CONCATENATE("<",C$1,">",C24,"</",C$1,">") -> <type></type> | Q24: =CONCATENATE("<",D$1,">",D24,"</",D$1,">") -> <icon>&lt;icon type=&quot;c_Train&quot;&gt;&lt;/icon&gt;</icon> | R24: =CONCATENATE("<",E$1,">",E24,"</",E$1,">") -> <text>c_Train</text> | S24: =CONCATENATE("<",F$1,">",F24,"</",F$1,">") -> <changeFrom></changeFrom> | T24: =CONCATENATE("<",G$1,">",G24,"</",G$1,">") -> <changeTo></changeTo> | U24: =IF(H24<>"",CONCATENATE("<",H$1,">",H24,".mp3","</",H$1,">"),"") -> <mp3>H183.mp3</mp3> | V24: =IF(I24<>"",CONCATENATE("<",I$1,">",I24,".mp3","</",I$1,">"),"") | W24: =IF(J24<>"",CONCATENATE("<",J$1,">",J24,".mp3","</",J$1,">"),"") | X24: =IF(K24<>"",CONCATENATE("<",K$1,">",K24,".mp3","</",K$1,">"),"") | Y24: =CONCATENATE("<announcement>",N24,O24,P24,Q24,R24,S24,T24,U24,V24,W24,X24,"</announcement>") -> <announcement><displayName>c_Train</displayName><duration>5</duration><type></type><icon>&lt;icon type=&quot;c_Train&quot;&gt;&lt;/icon&gt;</icon><text>c_Train</text><changeFrom></changeFrom><changeTo></changeTo><mp3>H183.mp3</mp3></announcement>
A25: =iconList!B25 -> c_TrainEnd | B25: 5 | D25: =iconList!A25&iconList!B25&iconList!C25 -> &lt;icon type=&quot;c_TrainEnd&quot;&gt;&lt;/icon&gt; | E25: =iconList!B25 -> c_TrainEnd | H25: H182 | N25: =CONCATENATE("<",A$1,">",A25,"</",A$1,">") -> <displayName>c_TrainEnd</displayName> | O25: =CONCATENATE("<",B$1,">",B25,"</",B$1,">") -> <duration>5</duration> | P25: =CONCATENATE("<",C$1,">",C25,"</",C$1,">") -> <type></type> | Q25: =CONCATENATE("<",D$1,">",D25,"</",D$1,">") -> <icon>&lt;icon type=&quot;c_TrainEnd&quot;&gt;&lt;/icon&gt;</icon> | R25: =CONCATENATE("<",E$1,">",E25,"</",E$1,">") -> <text>c_TrainEnd</text> | S25: =CONCATENATE("<",F$1,">",F25,"</",F$1,">") -> <changeFrom></changeFrom> | T25: =CONCATENATE("<",G$1,">",G25,"</",G$1,">") -> <changeTo></changeTo> | U25: =IF(H25<>"",CONCATENATE("<",H$1,">",H25,".mp3","</",H$1,">"),"") -> <mp3>H182.mp3</mp3> | V25: =IF(I25<>"",CONCATENATE("<",I$1,">",I25,".mp3","</",I$1,">"),"") | W25: =IF(J25<>"",CONCATENATE("<",J$1,">",J25,".mp3","</",J$1,">"),"") | X25: =IF(K25<>"",CONCATENATE("<",K$1,">",K25,".mp3","</",K$1,">"),"") | Y25: =CONCATENATE("<announcement>",N25,O25,P25,Q25,R25,S25,T25,U25,V25,W25,X25,"</announcement>") -> <announcement><displayName>c_TrainEnd</displayName><duration>5</duration><type></type><icon>&lt;icon type=&quot;c_TrainEnd&quot;&gt;&lt;/icon&gt;</icon><text>c_TrainEnd</text><changeFrom></changeFrom><changeTo></changeTo><mp3>H182.mp3</mp3></announcement>
A26: =iconList!B26 -> c_Tram | B26: 5 | D26: =iconList!A26&iconList!B26&iconList!C26 -> &lt;icon type=&quot;c_Tram&quot;&gt;&lt;/icon&gt; | E26: =iconList!B26 -> c_Tram | H26: H201 | N26: =CONCATENATE("<",A$1,">",A26,"</",A$1,">") -> <displayName>c_Tram</displayName> | O26: =CONCATENATE("<",B$1,">",B26,"</",B$1,">") -> <duration>5</duration> | P26: =CONCATENATE("<",C$1,">",C26,"</",C$1,">") -> <type></type> | Q26: =CONCATENATE("<",D$1,">",D26,"</",D$1,">") -> <icon>&lt;icon type=&quot;c_Tram&quot;&gt;&lt;/icon&gt;</icon> | R26: =CONCATENATE("<",E$1,">",E26,"</",E$1,">") -> <text>c_Tram</text> | S26: =CONCATENATE("<",F$1,">",F26,"</",F$1,">") -> <changeFrom></changeFrom> | T26: =CONCATENATE("<",G$1,">",G26,"</",G$1,">") -> <changeTo></changeTo> | U26: =IF(H26<>"",CONCATENATE("<",H$1,">",H26,".mp3","</",H$1,">"),"") -> <mp3>H201.mp3</mp3> | V26: =IF(I26<>"",CONCATENATE("<",I$1,">",I26,".mp3","</",I$1,">"),"") | W26: =IF(J26<>"",CONCATENATE("<",J$1,">",J26,".mp3","</",J$1,">"),"") | X26: =IF(K26<>"",CONCATENATE("<",K$1,">",K26,".mp3","</",K$1,">"),"") | Y26: =CONCATENATE("<announcement>",N26,O26,P26,Q26,R26,S26,T26,U26,V26,W26,X26,"</announcement>") -> <announcement><displayName>c_Tram</displayName><duration>5</duration><type></type><icon>&lt;icon type=&quot;c_Tram&quot;&gt;&lt;/icon&gt;</icon><text>c_Tram</text><changeFrom></changeFrom><changeTo></changeTo><mp3>H201.mp3</mp3></announcement>
A27: =iconList!B27 -> c_Trolleybus | B27: 5 | D27: =iconList!A27&iconList!B27&iconList!C27 -> &lt;icon type=&quot;c_Trolleybus&quot;&gt;&lt;/icon&gt; | E27: =iconList!B27 -> c_Trolleybus | H27: H202 | N27: =CONCATENATE("<",A$1,">",A27,"</",A$1,">") -> <displayName>c_Trolleybus</displayName> | O27: =CONCATENATE("<",B$1,">",B27,"</",B$1,">") -> <duration>5</duration> | P27: =CONCATENATE("<",C$1,">",C27,"</",C$1,">") -> <type></type> | Q27: =CONCATENATE("<",D$1,">",D27,"</",D$1,">") -> <icon>&lt;icon type=&quot;c_Trolleybus&quot;&gt;&lt;/icon&gt;</icon> | R27: =CONCATENATE("<",E$1,">",E27,"</",E$1,">") -> <text>c_Trolleybus</text> | S27: =CONCATENATE("<",F$1,">",F27,"</",F$1,">") -> <changeFrom></changeFrom> | T27: =CONCATENATE("<",G$1,">",G27,"</",G$1,">") -> <changeTo></changeTo> | U27: =IF(H27<>"",CONCATENATE("<",H$1,">",H27,".mp3","</",H$1,">"),"") -> <mp3>H202.mp3</mp3> | V27: =IF(I27<>"",CONCATENATE("<",I$1,">",I27,".mp3","</",I$1,">"),"") | W27: =IF(J27<>"",CONCATENATE("<",J$1,">",J27,".mp3","</",J$1,">"),"") | X27: =IF(K27<>"",CONCATENATE("<",K$1,">",K27,".mp3","</",K$1,">"),"") | Y27: =CONCATENATE("<announcement>",N27,O27,P27,Q27,R27,S27,T27,U27,V27,W27,X27,"</announcement>") -> <announcement><displayName>c_Trolleybus</displayName><duration>5</duration><type></type><icon>&lt;icon type=&quot;c_Trolleybus&quot;&gt;&lt;/icon&gt;</icon><text>c_Trolleybus</text><changeFrom></changeFrom><changeTo></changeTo><mp3>H202.mp3</mp3></announcement>
A28: =iconList!B28 -> c_UndergroundA | B28: 5 | D28: =iconList!A28&iconList!B28&iconList!C28 -> &lt;icon type=&quot;c_UndergroundA&quot;&gt;&lt;/icon&gt; | E28: =iconList!B28 -> c_UndergroundA | H28: H203 | N28: =CONCATENATE("<",A$1,">",A28,"</",A$1,">") -> <displayName>c_UndergroundA</displayName> | O28: =CONCATENATE("<",B$1,">",B28,"</",B$1,">") -> <duration>5</duration> | P28: =CONCATENATE("<",C$1,">",C28,"</",C$1,">") -> <type></type> | Q28: =CONCATENATE("<",D$1,">",D28,"</",D$1,">") -> <icon>&lt;icon type=&quot;c_UndergroundA&quot;&gt;&lt;/icon&gt;</icon> | R28: =CONCATENATE("<",E$1,">",E28,"</",E$1,">") -> <text>c_UndergroundA</text> | S28: =CONCATENATE("<",F$1,">",F28,"</",F$1,">") -> <changeFrom></changeFrom> | T28: =CONCATENATE("<",G$1,">",G28,"</",G$1,">") -> <changeTo></changeTo> | U28: =IF(H28<>"",CONCATENATE("<",H$1,">",H28,".mp3","</",H$1,">"),"") -> <mp3>H203.mp3</mp3> | V28: =IF(I28<>"",CONCATENATE("<",I$1,">",I28,".mp3","</",I$1,">"),"") | W28: =IF(J28<>"",CONCATENATE("<",J$1,">",J28,".mp3","</",J$1,">"),"") | X28: =IF(K28<>"",CONCATENATE("<",K$1,">",K28,".mp3","</",K$1,">"),"") | Y28: =CONCATENATE("<announcement>",N28,O28,P28,Q28,R28,S28,T28,U28,V28,W28,X28,"</announcement>") -> <announcement><displayName>c_UndergroundA</displayName><duration>5</duration><type></type><icon>&lt;icon type=&quot;c_UndergroundA&quot;&gt;&lt;/icon&gt;</icon><text>c_UndergroundA</text><changeFrom></changeFrom><changeTo></changeTo><mp3>H203.mp3</mp3></announcement>
A29: =iconList!B29 -> c_UndergroundB | B29: 5 | D29: =iconList!A29&iconList!B29&iconList!C29 -> &lt;icon type=&quot;c_UndergroundB&quot;&gt;&lt;/icon&gt; | E29: =iconList!B29 -> c_UndergroundB | H29: H204 | N29: =CONCATENATE("<",A$1,">",A29,"</",A$1,">") -> <displayName>c_UndergroundB</displayName> | O29: =CONCATENATE("<",B$1,">",B29,"</",B$1,">") -> <duration>5</duration> | P29: =CONCATENATE("<",C$1,">",C29,"</",C$1,">") -> <type></type> | Q29: =CONCATENATE("<",D$1,">",D29,"</",D$1,">") -> <icon>&lt;icon type=&quot;c_UndergroundB&quot;&gt;&lt;/icon&gt;</icon> | R29: =CONCATENATE("<",E$1,">",E29,"</",E$1,">") -> <text>c_UndergroundB</text> | S29: =CONCATENATE("<",F$1,">",F29,"</",F$1,">") -> <changeFrom></changeFrom> | T29: =CONCATENATE("<",G$1,">",G29,"</",G$1,">") -> <changeTo></changeTo> | U29: =IF(H29<>"",CONCATENATE("<",H$1,">",H29,".mp3","</",H$1,">"),"") -> <mp3>H204.mp3</mp3> | V29: =IF(I29<>"",CONCATENATE("<",I$1,">",I29,".mp3","</",I$1,">"),"") | W29: =IF(J29<>"",CONCATENATE("<",J$1,">",J29,".mp3","</",J$1,">"),"") | X29: =IF(K29<>"",CONCATENATE("<",K$1,">",K29,".mp3","</",K$1,">"),"") | Y29: =CONCATENATE("<announcement>",N29,O29,P29,Q29,R29,S29,T29,U29,V29,W29,X29,"</announcement>") -> <announcement><displayName>c_UndergroundB</displayName><duration>5</duration><type></type><icon>&lt;icon type=&quot;c_UndergroundB&quot;&gt;&lt;/icon&gt;</icon><text>c_UndergroundB</text><changeFrom></changeFrom><changeTo></changeTo><mp3>H204.mp3</mp3></announcement>
A30: =iconList!B30 -> c_UndergroundC | B30: 5 | D30: =iconList!A30&iconList!B30&iconList!C30 -> &lt;icon type=&quot;c_UndergroundC&quot;&gt;&lt;/icon&gt; | E30: =iconList!B30 -> c_UndergroundC | H30: H205 | N30: =CONCATENATE("<",A$1,">",A30,"</",A$1,">") -> <displayName>c_UndergroundC</displayName> | O30: =CONCATENATE("<",B$1,">",B30,"</",B$1,">") -> <duration>5</duration> | P30: =CONCATENATE("<",C$1,">",C30,"</",C$1,">") -> <type></type> | Q30: =CONCATENATE("<",D$1,">",D30,"</",D$1,">") -> <icon>&lt;icon type=&quot;c_UndergroundC&quot;&gt;&lt;/icon&gt;</icon> | R30: =CONCATENATE("<",E$1,">",E30,"</",E$1,">") -> <text>c_UndergroundC</text> | S30: =CONCATENATE("<",F$1,">",F30,"</",F$1,">") -> <changeFrom></changeFrom> | T30: =CONCATENATE("<",G$1,">",G30,"</",G$1,">") -> <changeTo></changeTo> | U30: =IF(H30<>"",CONCATENATE("<",H$1,">",H30,".mp3","</",H$1,">"),"") -> <mp3>H205.mp3</mp3> | V30: =IF(I30<>"",CONCATENATE("<",I$1,">",I30,".mp3","</",I$1,">"),"") | W30: =IF(J30<>"",CONCATENATE("<",J$1,">",J30,".mp3","</",J$1,">"),"") | X30: =IF(K30<>"",CONCATENATE("<",K$1,">",K30,".mp3","</",K$1,">"),"") | Y30: =CONCATENATE("<announcement>",N30,O30,P30,Q30,R30,S30,T30,U30,V30,W30,X30,"</announcement>") -> <announcement><displayName>c_UndergroundC</displayName><duration>5</duration><type></type><icon>&lt;icon type=&quot;c_UndergroundC&quot;&gt;&lt;/icon&gt;</icon><text>c_UndergroundC</text><changeFrom></changeFrom><changeTo></changeTo><mp3>H205.mp3</mp3></announcement>
A31: =iconList!B31 -> c_UndergroundD | B31: 5 | D31: =iconList!A31&iconList!B31&iconList!C31 -> &lt;icon type=&quot;c_UndergroundD&quot;&gt;&lt;/icon&gt; | E31: =iconList!B31 -> c_UndergroundD | H31: H206 | N31: =CONCATENATE("<",A$1,">",A31,"</",A$1,">") -> <displayName>c_UndergroundD</displayName> | O31: =CONCATENATE("<",B$1,">",B31,"</",B$1,">") -> <duration>5</duration> | P31: =CONCATENATE("<",C$1,">",C31,"</",C$1,">") -> <type></type> | Q31: =CONCATENATE("<",D$1,">",D31,"</",D$1,">") -> <icon>&lt;icon type=&quot;c_UndergroundD&quot;&gt;&lt;/icon&gt;</icon> | R31: =CONCATENATE("<",E$1,">",E31,"</",E$1,">") -> <text>c_UndergroundD</text> | S31: =CONCATENATE("<",F$1,">",F31,"</",F$1,">") -> <changeFrom></changeFrom> | T31: =CONCATENATE("<",G$1,">",G31,"</",G$1,">") -> <changeTo></changeTo> | U31: =IF(H31<>"",CONCATENATE("<",H$1,">",H31,".mp3","</",H$1,">"),"") -> <mp3>H206.mp3</mp3> | V31: =IF(I31<>"",CONCATENATE("<",I$1,">",I31,".mp3","</",I$1,">"),"") | W31: =IF(J31<>"",CONCATENATE("<",J$1,">",J31,".mp3","</",J$1,">"),"") | X31: =IF(K31<>"",CONCATENATE("<",K$1,">",K31,".mp3","</",K$1,">"),"") | Y31: =CONCATENATE("<announcement>",N31,O31,P31,Q31,R31,S31,T31,U31,V31,W31,X31,"</announcement>") -> <announcement><displayName>c_UndergroundD</displayName><duration>5</duration><type></type><icon>&lt;icon type=&quot;c_UndergroundD&quot;&gt;&lt;/icon&gt;</icon><text>c_UndergroundD</text><changeFrom></changeFrom><changeTo></changeTo><mp3>H206.mp3</mp3></announcement>
... A34: =iconList!B34 -> c_ReplacementStop | B34: 5 | D34: =iconList!A34&iconList!B34&iconList!C34 -> &lt;icon type=&quot;c_ReplacementStop&quot;&gt;&lt;/icon&gt; | E34: =iconList!B34 -> c_ReplacementStop | H34: H209 | N34: =CONCATENATE("<",A$1,">",A34,"</",A$1,">") -> <displayName>c_ReplacementStop</displayName> | O34: =CONCATENATE("<",B$1,">",B34,"</",B$1,">") -> <duration>5</duration> | P34: =CONCATENATE("<",C$1,">",C34,"</",C$1,">") -> <type></type> | Q34: =CONCATENATE("<",D$1,">",D34,"</",D$1,">") -> <icon>&lt;icon type=&quot;c_ReplacementStop&quot;&gt;&lt;/icon&gt;</icon> | R34: =CONCATENATE("<",E$1,">",E34,"</",E$1,">") -> <text>c_ReplacementStop</text> | S34: =CONCATENATE("<",F$1,">",F34,"</",F$1,">") -> <changeFrom></changeFrom> | T34: =CONCATENATE("<",G$1,">",G34,"</",G$1,">") -> <changeTo></changeTo> | U34: =IF(H34<>"",CONCATENATE("<",H$1,">",H34,".mp3","</",H$1,">"),"") -> <mp3>H209.mp3</mp3> | V34: =IF(I34<>"",CONCATENATE("<",I$1,">",I34,".mp3","</",I$1,">"),"") | W34: =IF(J34<>"",CONCATENATE("<",J$1,">",J34,".mp3","</",J$1,">"),"") | X34: =IF(K34<>"",CONCATENATE("<",K$1,">",K34,".mp3","</",K$1,">"),"") | Y34: =CONCATENATE("<announcement>",N34,O34,P34,Q34,R34,S34,T34,U34,V34,W34,X34,"</announcement>") -> <announcement><displayName>c_ReplacementStop</displayName><duration>5</duration><type></type><icon>&lt;icon type=&quot;c_ReplacementStop&quot;&gt;&lt;/icon&gt;</icon><text>c_ReplacementStop</text><changeFrom></changeFrom><changeTo></changeTo><mp3>H209.mp3</mp3></announcement>

Sheet mergedResult
A1: =_xlfn.TEXTJOIN("",TRUE,"<announcementList>",slozit!Y:Y,"</announcementList>") -> <announcementList><announcement><displayName>c_Accessible</displayName><duration>5</duration><type></type><icon>&lt;icon type=&quot;c_Accessible&quot;&gt;&lt;/icon&gt;</icon><text>c_Accessible</text><changeFrom></changeFrom><changeTo></changeTo><mp3>H239.mp3</mp3></announcement><announcement><displayName>c_Air</displayName><duration>5</duration><type></type><icon>&lt;icon type=&quot;c_Air&quot;&gt;&lt;/icon&gt;</icon><text>c_Air</text><changeFrom></changeFrom><changeTo></changeTo><mp3>H340.mp3</mp3></announcement><announcement><displayName>c_Bus</displayName><duration>5</duration><type></type><icon>&lt;icon type=&quot;c_Bus&quot;&gt;&lt;/icon&gt;</icon><text>c_Bus</text><changeFrom></changeFrom><changeTo></changeTo><mp3>H240.mp3</mp3></announcement><announcement><displayName>c_Congestion</displayName><duration>5</duration><type></type><icon>&lt;icon type=&quot;c_Congestion&quot;&gt;&lt;/icon&gt;</icon><text>c_Congestion</text><changeFrom></changeFrom><changeTo></changeTo><mp3>H260.mp3</mp3></announcement><announcement><displayName>c_Diversion</displayName><duration>5</duration><type></type><icon>&lt;icon type=&quot;c_Diversion&quot;&gt;&lt;/icon&gt;</icon><text>c_Diversion</text><changeFrom></changeFrom><changeTo></changeTo><mp3>H179.mp3</mp3></announcement><announcement><displayName>c_Exclamation</displayName><duration>5</duration><type></type><icon>&lt;icon type=&quot;c_Exclamation&quot;&gt;&lt;/icon&gt;</icon><text>c_Exclamation</text><changeFrom></changeFrom><changeTo></changeTo><mp3>H281.mp3</mp3></announcement><announcement><displayName>c_Ferry</displayName><duration>5</duration><type></type><icon>&lt;icon type=&quot;c_Ferry&quot;&gt;&lt;/icon&gt;</icon><text>c_Ferry</text><changeFrom></changeFrom><changeTo></changeTo><mp3>H284.mp3</mp3></announcement><announcement><displayName>c_Funicular</displayName><duration>5</duration><type></type><icon>&lt;icon type=&quot;c_Funicular&quot;&gt;&lt;/icon&gt;</icon><text>c_Funicular</text><changeFrom></changeFrom><changeTo></changeTo></announcement><announcement><displayName>c_GoFurther</displayName><duration>5</duration><type></type><icon>&lt;icon type=&quot;c_GoFurther&quot;&gt;&lt;/icon&gt;</icon><text>c_GoFurther</text><changeFrom></changeFrom><changeTo></changeTo><mp3>H279.mp3</mp3></announcement><announcement><displayName>c_Children</displayName><duration>5</duration><type></type><icon>&lt;icon type=&quot;c_Children&quot;&gt;&lt;/icon&gt;</icon><text>c_Children</text><changeFrom></changeFrom><changeTo></changeTo></announcement><announcement><displayName>c_Info</displayName><duration>5</duration><type></type><icon>&lt;icon type=&quot;c_Info&quot;&gt;&lt;/icon&gt;</icon><text>c_Info</text><changeFrom></changeFrom><changeTo></changeTo><mp3>H280.mp3</mp3></announcement><announcement><displayName>c_Luggage</displayName><duration>5</duration><type></type><icon>&lt;icon type=&quot;c_Luggage&quot;&gt;&lt;/icon&gt;</icon><text>c_Luggage</text><changeFrom>6,8</changeFrom><changeTo>7</changeTo></announcement><announcement><displayName>c_Night</displayName><duration>5</duration><type></type><icon>&lt;icon type=&quot;c_Night&quot;&gt;&lt;/icon&gt;</icon><text>c_Night</text><changeFrom>123</changeFrom><changeTo>XS2</changeTo></announcement><announcement><displayName>c_NightInv</displayName><duration>5</duration><type></type><icon>&lt;icon type=&quot;c_NightInv&quot;&gt;&lt;/icon&gt;</icon><text>c_NightInv</text><changeFrom></changeFrom><changeTo></changeTo></announcement><announcement><displayName>c_NoFood</displayName><duration>5</duration><type></type><icon>&lt;icon type=&quot;c_NoFood&quot;&gt;&lt;/icon&gt;</icon><text>c_NoFood</text><changeFrom></changeFrom><changeTo></changeTo></announcement><announcement><displayName>c_NoFoodInv</displayName><duration>5</duration><type></type><icon>&lt;icon type=&quot;c_NoFoodInv&quot;&gt;&lt;/icon&gt;</icon><text>c_NoFoodInv</text><changeFrom></changeFrom><changeTo></changeTo></announcement><announcement><displayName>c_Pid</displayName><duration>5</duration><type></type><icon>&lt;icon type=&quot;c_Pid&quot;&gt;&lt;/icon&gt;</icon><text>c_Pid</text><changeFrom></changeFrom><changeTo></changeTo></announcement><announcement><displayName>c_Pram</displayName><duration>5</duration><type></type><icon>&lt;icon type=&quot;c_Pram&quot;&gt;&lt;/icon&gt;</icon><text>c_Pram</text><changeFrom></changeFrom><changeTo></changeTo></announcement><announcement><displayName>c_ReplacementService</displayName><duration>5</duration><type></type><icon>&lt;icon type=&quot;c_ReplacementService&quot;&gt;&lt;/icon&gt;</icon><text>c_ReplacementService</text><changeFrom></changeFrom><changeTo></changeTo><mp3>H350.mp3</mp3></announcement><announcement><displayName>c_RequestStop</displayName><duration>5</duration><type></type><icon>&lt;icon type=&quot;c_RequestStop&quot;&gt;&lt;/icon&gt;</icon><text>c_RequestStop</text><changeFrom></changeFrom><changeTo></changeTo><mp3>H205.mp3</mp3></announcement><announcement><displayName>c_RequestStopInv</displayName><duration>5</duration><type></type><icon>&lt;icon type=&quot;c_RequestStopInv&quot;&gt;&lt;/icon&gt;</icon><text>c_RequestStopInv</text><changeFrom></changeFrom><changeTo></changeTo><mp3>H162.mp3</mp3></announcement><announcement><displayName>c_SBahn</displayName><duration>5</duration><type></type><icon>&lt;icon type=&quot;c_SBahn&quot;&gt;&lt;/icon&gt;</icon><text>c_SBahn</text><changeFrom></changeFrom><changeTo></changeTo><mp3>H164.mp3</mp3></announcement><announcement><displayName>c_Train</displayName><duration>5</duration><type></type><icon>&lt;icon type=&quot;c_Train&quot;&gt;&lt;/icon&gt;</icon><text>c_Train</text><changeFrom></changeFrom><changeTo></changeTo><mp3>H183.mp3</mp3></announcement><announcement><displayName>c_TrainEnd</displayName><duration>5</duration><type></type><icon>&lt;icon type=&quot;c_TrainEnd&quot;&gt;&lt;/icon&gt;</icon><text>c_TrainEnd</text><changeFrom></changeFrom><changeTo></changeTo><mp3>H182.mp3</mp3></announcement><announcement><displayName>c_Tram</displayName><duration>5</duration><type></type><icon>&lt;icon type=&quot;c_Tram&quot;&gt;&lt;/icon&gt;</icon><text>c_Tram</text><changeFrom></changeFrom><changeTo></changeTo><mp3>H201.mp3</mp3></announcement><announcement><displayName>c_Trolleybus</displayName><duration>5</duration><type></type><icon>&lt;icon type=&quot;c_Trolleybus&quot;&gt;&lt;/icon&gt;</icon><text>c_Trolleybus</text><changeFrom></changeFrom><changeTo></changeTo><mp3>H202.mp3</mp3></announcement><announcement><displayName>c_UndergroundA</displayName><duration>5</duration><type></type><icon>&lt;icon type=&quot;c_UndergroundA&quot;&gt;&lt;/icon&gt;</icon><text>c_UndergroundA</text><changeFrom></changeFrom><changeTo></changeTo><mp3>H203.mp3</mp3></announcement><announcement><displayName>c_UndergroundB</displayName><duration>5</duration><type></type><icon>&lt;icon type=&quot;c_UndergroundB&quot;&gt;&lt;/icon&gt;</icon><text>c_UndergroundB</text><changeFrom></changeFrom><changeTo></changeTo><mp3>H204.mp3</mp3></announcement><announcement><displayName>c_UndergroundC</displayName><duration>5</duration><type></type><icon>&lt;icon type=&quot;c_UndergroundC&quot;&gt;&lt;/icon&gt;</icon><text>c_UndergroundC</text><changeFrom></changeFrom><changeTo></changeTo><mp3>H205.mp3</mp3></announcement><announcement><displayName>c_UndergroundD</displayName><duration>5</duration><type></type><icon>&lt;icon type=&quot;c_UndergroundD&quot;&gt;&lt;/icon&gt;</icon><text>c_UndergroundD</text><changeFrom></changeFrom><changeTo></changeTo><mp3>H206.mp3</mp3></announcement><announcement><displayName>c_WheelChair</displayName><duration>5</duration><type></type><icon>&lt;icon type=&quot;c_WheelChair&quot;&gt;&lt;/icon&gt;</icon><text>c_WheelChair</text><changeFrom></changeFrom><changeTo></changeTo><mp3>H207.mp3</mp3></announcement><announcement><displayName>c_WheelChairLine </displayName><duration>5</duration><type></type><icon>&lt;icon type=&quot;c_WheelChairLine &quot;&gt;&lt;/icon&gt;</icon><text>c_WheelChairLine </text><changeFrom></changeFrom><changeTo></changeTo><mp3>H208.mp3</mp3></announcement><announcement><displayName>c_ReplacementStop</displayName><duration>5</duration><type></type><icon>&lt;icon type=&quot;c_ReplacementStop&quot;&gt;&lt;/icon&gt;</icon><text>c_ReplacementStop</text><changeFrom></changeFrom><changeTo></changeTo><mp3>H209.mp3</mp3></announcement></announcementList>

Sheet Namluveno k 12-2020
A1: !!! NAMLUVENO - JEN DISTRIBUOVAT S NOVOU DÁVKOU DAT DOPRAVCŮM !!!
A3: OIS | B3: Název zst. | C3: číslo CIS
A4: 5703 | B4: Svatý Jan,Radobyl,rozcestí | C4: 34172
A5: 5712 | B5: Svatý Jan,Řadovy | C5: 34181
A6: 5736 | B6: Tochovice,,rozcestí | C6: 35954
A7: 5737 | B7: Tochovice,,rozcestí k železniční stanici | C7: 35955
A8: 5773 | B8: Višňová | C8: 39637
A9: 5774 | B9: Višňová,,hájenka | C9: 39638
A10: 5866 | B10: Zduchovice | C10: 41798
A11: 5873 | B11: Horčápsko,,rozcestí | C11: 44443
A12: 5909 | B12: Svaté Pole,,U kostela | C12: 57613
A13: 5913 | B13: Obory,,křižovatka | C13: 62619
A14: 5914 | B14: Nečín,,křižovatka | C14: 62620
A15: 6975 | B15: Narysov | C15: 22614
... A143: 31889 | B143: Velký Bor | C143: 38964
A144: BCZM | B144: Březnice,ČZM | C144: 3176
A145: Bkov | B145: Březnice,KOVO | C145: 3177
A146: Bpo | B146: Březnice,Počápelská | C146: 3172
A147: Brzst | B147: Březnice,rozcestí k železniční stanici | C147: 3174
A148: Bsub | B148: Březnice,Sublima | C148: 3178
A149: Hrej | B149: Hrejkovice | C149: 10755
A150: HrejPL | B150: Hrejkovice,Pechova Lhota | C150: 10761
A151: KonV | B151: Kostelec nad Vltavou | C151: 15513
A152: VBzst | B152: Velký Bor,železniční zastávka | C152: 38965

Sheet ciselnik
A1: Air
A2: Bus
A3: Congestion
A4: Diversion
A5: Exclamation
A6: Ferry
A7: Funicular
A8: GoFurther
A9: Info
A10: Luggage
A11: Night
A12: NoFood
... A24: WheelChair

Sheet iconList
F1: announcement | G1: stopName
A2: &lt;icon type=&quot; | B2: c_Accessible | C2: &quot;&gt;&lt;/icon&gt; | F2: x | G2: x
A3: &lt;icon type=&quot; | B3: c_Air | C3: &quot;&gt;&lt;/icon&gt; | F3: x | G3: x
A4: &lt;icon type=&quot; | B4: c_Bus | C4: &quot;&gt;&lt;/icon&gt; | F4: x | G4: x
A5: &lt;icon type=&quot; | B5: c_Congestion | C5: &quot;&gt;&lt;/icon&gt; | F5: x | G5: x
A6: &lt;icon type=&quot; | B6: c_Diversion | C6: &quot;&gt;&lt;/icon&gt; | F6: x | G6: x
A7: &lt;icon type=&quot; | B7: c_Exclamation | C7: &quot;&gt;&lt;/icon&gt; | F7: i | G7: nic
A8: &lt;icon type=&quot; | B8: c_Ferry | C8: &quot;&gt;&lt;/icon&gt; | F8: x | G8: x
A9: &lt;icon type=&quot; | B9: c_Funicular | C9: &quot;&gt;&lt;/icon&gt; | F9: x | G9: c
A10: &lt;icon type=&quot; | B10: c_GoFurther | C10: &quot;&gt;&lt;/icon&gt; | F10: x | G10: c
A11: &lt;icon type=&quot; | B11: c_Children | C11: &quot;&gt;&lt;/icon&gt; | F11: i | G11: nic
A12: &lt;icon type=&quot; | B12: c_Info | C12: &quot;&gt;&lt;/icon&gt; | F12: x | G12: x
A13: &lt;icon type=&quot; | B13: c_Luggage | C13: &quot;&gt;&lt;/icon&gt; | F13: x | G13: x
... A20: &lt;icon type=&quot; | B20: c_ReplacementService | C20: &quot;&gt;&lt;/icon&gt; | F20: nic | G20: x
A21: &lt;icon type=&quot; | B21: c_RequestStop | C21: &quot;&gt;&lt;/icon&gt; | G21: x
A22: &lt;icon type=&quot; | B22: c_RequestStopInv | C22: &quot;&gt;&lt;/icon&gt; | F22: nic | G22: ?
A23: &lt;icon type=&quot; | B23: c_SBahn | C23: &quot;&gt;&lt;/icon&gt; | F23: i | G23: nic
A24: &lt;icon type=&quot; | B24: c_Train | C24: &quot;&gt;&lt;/icon&gt; | F24: x | G24: x
A25: &lt;icon type=&quot; | B25: c_TrainEnd | C25: &quot;&gt;&lt;/icon&gt; | F25: x | G25: x
A26: &lt;icon type=&quot; | B26: c_Tram | C26: &quot;&gt;&lt;/icon&gt; | F26: x | G26: x
A27: &lt;icon type=&quot; | B27: c_Trolleybus | C27: &quot;&gt;&lt;/icon&gt; | F27: x | G27: x
A28: &lt;icon type=&quot; | B28: c_UndergroundA | C28: &quot;&gt;&lt;/icon&gt; | F28: nic | G28: x
A29: &lt;icon type=&quot; | B29: c_UndergroundB | C29: &quot;&gt;&lt;/icon&gt; | F29: nic | G29: x
A30: &lt;icon type=&quot; | B30: c_UndergroundC | C30: &quot;&gt;&lt;/icon&gt; | F30: nic | G30: x
A31: &lt;icon type=&quot; | B31: c_UndergroundD | C31: &quot;&gt;&lt;/icon&gt; | F31: nic | G31: x
A32: &lt;icon type=&quot; | B32: c_WheelChair | C32: &quot;&gt;&lt;/icon&gt; | F32: x | G32: x
A33: &lt;icon type=&quot; | B33: c_WheelChairLine | C33: &quot;&gt;&lt;/icon&gt; | F33: i | G33: nic
A34: &lt;icon type=&quot; | B34: c_ReplacementStop | C34: &quot;&gt;&lt;/icon&gt; | F34: i | G34: nic

Sheet stopPointGenerator
